<?xml version="1.0" encoding="utf-8"?>
<!-- =================================================================================== -->
<!-- |    This document was autogenerated by xacro from arm.urdf.xacro                 | -->
<!-- |    EDITING THIS FILE BY HAND IS NOT RECOMMENDED                                 | -->
<!-- =================================================================================== -->
<robot name="arm">
  <material name="black">
    <color rgba="0.0 0.0 0.0 1.0"/>
  </material>
  <material name="blue">
    <color rgba="0.0 0.0 0.8 1.0"/>
  </material>
  <material name="green">
    <color rgba="0.0 0.8 0.0 1.0"/>
  </material>
  <material name="grey">
    <color rgba="0.2 0.2 0.2 1.0"/>
  </material>
  <material name="orange">
    <color rgba="1.0 0.423529411765 0.0392156862745 1.0"/>
  </material>
  <material name="brown">
    <color rgba="0.870588235294 0.811764705882 0.764705882353 1.0"/>
  </material>
  <material name="red">
    <color rgba="0.8 0.0 0.0 1.0"/>
  </material>
  <material name="white">
    <color rgba="1.0 1.0 1.0 1.0"/>
  </material>
  <!--Link-->
  <link name="world"/>
  <link name="base_link">
    <visual>
      <geometry>
        <mesh filename="package://nebulizador_description/meshes/arm/visual/base_link.stl"/>
      </geometry>
    </visual>
    <!--collision>
        <geometry>
          <mesh filename="package://nebulizador_description/meshes/arm/collision/${name}.dae"/>
        </geometry>
      </collision-->
    <inertial>
      <mass value="0.385"/>
      <inertia ixx="0.012388" ixy="4.9304e-06" ixz="-0.00013633" iyy="0.015605" iyz="-1.7128e-05" izz="0.013469"/>
    </inertial>
  </link>
  <link name="link_1">
    <visual>
      <geometry>
        <mesh filename="package://nebulizador_description/meshes/arm/visual/link_1.stl"/>
      </geometry>
    </visual>
    <!--collision>
        <geometry>
          <mesh filename="package://nebulizador_description/meshes/arm/collision/${name}.dae"/>
        </geometry>
      </collision-->
    <inertial>
      <mass value="0.385"/>
      <inertia ixx="0.022235" ixy="-6.2582e-05" ixz="-0.0017584" iyy="0.015421" iyz="-0.0002643" izz="0.015075"/>
    </inertial>
  </link>
  <link name="link_2">
    <visual>
      <geometry>
        <mesh filename="package://nebulizador_description/meshes/arm/visual/link_2.stl"/>
      </geometry>
    </visual>
    <!--collision>
        <geometry>
          <mesh filename="package://nebulizador_description/meshes/arm/collision/${name}.dae"/>
        </geometry>
      </collision-->
    <inertial>
      <mass value="0.348"/>
      <inertia ixx="0.03751" ixy="6.5336e-05" ixz="0.00056744" iyy="0.030168" iyz="-0.00040066" izz="0.014053"/>
    </inertial>
  </link>
  <!-- Joint -->
  <joint name="world" type="fixed">
    <parent link="world"/>
    <child link="base_link"/>
    <origin rpy="0.0 0.0 0.0" xyz="0.0 0.0 0.0"/>
  </joint>
  <joint name="J1" type="revolute">
    <origin rpy="0 0 0" xyz="0 0 0.017"/>
    <parent link="base_link"/>
    <child link="link_1"/>
    <axis xyz="0 0 1"/>
    <dynamics damping="0.7" friction="0.7"/>
    <limit effort="30.0" lower="-1.5708" upper="1.5708" velocity="5.236"/>
  </joint>
  <joint name="J2" type="revolute">
    <origin rpy="0 0 0" xyz="-0.00838 0.19 0.06964"/>
    <parent link="link_1"/>
    <child link="link_2"/>
    <axis xyz="0 1 0"/>
    <dynamics damping="0.7" friction="0.7"/>
    <limit effort="30.0" lower="-0.7854" upper="0.7854" velocity="5.236"/>
  </joint>
  <transmission name="transmission_1">
    <type>transmission_interface/SimpleTransmission</type>
    <joint name="J1">
      <hardwareInterface>PositionJointInterface</hardwareInterface>
    </joint>
    <actuator name="motor_1">
      <hardwareInterface>PositionJointInterface</hardwareInterface>
      <mechanicalReduction>1</mechanicalReduction>
    </actuator>
  </transmission>
  <transmission name="transmission_2">
    <type>transmission_interface/SimpleTransmission</type>
    <joint name="J2">
      <hardwareInterface>PositionJointInterface</hardwareInterface>
    </joint>
    <actuator name="motor_2">
      <hardwareInterface>PositionJointInterface</hardwareInterface>
      <mechanicalReduction>1</mechanicalReduction>
    </actuator>
  </transmission>
  <!-- gazebo -->
  <gazebo>
    <plugin filename="libgazebo_ros_control.so" name="gazebo_ros_control">
      <robotNamespace>/arm</robotNamespace>
      <robotSimType>gazebo_ros_control/DefaultRobotHWSim</robotSimType>
    </plugin>
  </gazebo>
  <gazebo reference="base_link">
    <mu1>0.2</mu1>
    <mu2>0.2</mu2>
    <selfCollide>true</selfCollide>
    <!--     <turnGravityOff>true</turnGravityOff> -->
  </gazebo>
  <gazebo reference="link_1">
    <mu1>0.2</mu1>
    <mu2>0.2</mu2>
    <selfCollide>true</selfCollide>
    <!--     <turnGravityOff>true</turnGravityOff> -->
  </gazebo>
  <gazebo reference="link_2">
    <mu1>0.2</mu1>
    <mu2>0.2</mu2>
    <selfCollide>true</selfCollide>
    <!--     <turnGravityOff>true</turnGravityOff> -->
  </gazebo>
</robot>

